{
 "cells": [
  {
   "cell_type": "code",
   "execution_count": 6,
   "metadata": {},
   "outputs": [],
   "source": [
    "import psycopg2\n",
    "import pymongo\n",
    "from pymongo import MongoClient\n",
    "from pymongo.errors import ConnectionFailure\n",
    "from bson import json_util, ObjectId\n",
    "import pandas as pd"
   ]
  },
  {
   "cell_type": "code",
   "execution_count": 7,
   "metadata": {},
   "outputs": [],
   "source": [
    "conn = psycopg2.connect(database='postgres',user='postgres', password='')"
   ]
  },
  {
   "cell_type": "code",
   "execution_count": 9,
   "metadata": {},
   "outputs": [
    {
     "ename": "DatabaseError",
     "evalue": "Execution failed on sql 'SELECT row_to_json(europeansoccer) FROM europeansoccer': relation \"europeansoccer\" does not exist\nLINE 1: SELECT row_to_json(europeansoccer) FROM europeansoccer\n                                                ^\n",
     "output_type": "error",
     "traceback": [
      "\u001b[0;31m---------------------------------------------------------------------------\u001b[0m",
      "\u001b[0;31mProgrammingError\u001b[0m                          Traceback (most recent call last)",
      "\u001b[0;32m~/anaconda3/lib/python3.6/site-packages/pandas/io/sql.py\u001b[0m in \u001b[0;36mexecute\u001b[0;34m(self, *args, **kwargs)\u001b[0m\n\u001b[1;32m   1408\u001b[0m             \u001b[0;32melse\u001b[0m\u001b[0;34m:\u001b[0m\u001b[0;34m\u001b[0m\u001b[0m\n\u001b[0;32m-> 1409\u001b[0;31m                 \u001b[0mcur\u001b[0m\u001b[0;34m.\u001b[0m\u001b[0mexecute\u001b[0m\u001b[0;34m(\u001b[0m\u001b[0;34m*\u001b[0m\u001b[0margs\u001b[0m\u001b[0;34m)\u001b[0m\u001b[0;34m\u001b[0m\u001b[0m\n\u001b[0m\u001b[1;32m   1410\u001b[0m             \u001b[0;32mreturn\u001b[0m \u001b[0mcur\u001b[0m\u001b[0;34m\u001b[0m\u001b[0m\n",
      "\u001b[0;31mProgrammingError\u001b[0m: relation \"europeansoccer\" does not exist\nLINE 1: SELECT row_to_json(europeansoccer) FROM europeansoccer\n                                                ^\n",
      "\nDuring handling of the above exception, another exception occurred:\n",
      "\u001b[0;31mDatabaseError\u001b[0m                             Traceback (most recent call last)",
      "\u001b[0;32m<ipython-input-9-0f334f8ed110>\u001b[0m in \u001b[0;36m<module>\u001b[0;34m()\u001b[0m\n\u001b[0;32m----> 1\u001b[0;31m \u001b[0mdf\u001b[0m\u001b[0;34m=\u001b[0m\u001b[0mpd\u001b[0m\u001b[0;34m.\u001b[0m\u001b[0mread_sql\u001b[0m\u001b[0;34m(\u001b[0m\u001b[0;34m'''SELECT row_to_json(europeansoccer) FROM europeansoccer'''\u001b[0m\u001b[0;34m,\u001b[0m \u001b[0mcon\u001b[0m\u001b[0;34m=\u001b[0m\u001b[0mconn\u001b[0m\u001b[0;34m)\u001b[0m\u001b[0;34m\u001b[0m\u001b[0m\n\u001b[0m\u001b[1;32m      2\u001b[0m \u001b[0mdf\u001b[0m\u001b[0;34m.\u001b[0m\u001b[0mhead\u001b[0m\u001b[0;34m(\u001b[0m\u001b[0;36m3\u001b[0m\u001b[0;34m)\u001b[0m\u001b[0;34m\u001b[0m\u001b[0m\n",
      "\u001b[0;32m~/anaconda3/lib/python3.6/site-packages/pandas/io/sql.py\u001b[0m in \u001b[0;36mread_sql\u001b[0;34m(sql, con, index_col, coerce_float, params, parse_dates, columns, chunksize)\u001b[0m\n\u001b[1;32m    398\u001b[0m             \u001b[0msql\u001b[0m\u001b[0;34m,\u001b[0m \u001b[0mindex_col\u001b[0m\u001b[0;34m=\u001b[0m\u001b[0mindex_col\u001b[0m\u001b[0;34m,\u001b[0m \u001b[0mparams\u001b[0m\u001b[0;34m=\u001b[0m\u001b[0mparams\u001b[0m\u001b[0;34m,\u001b[0m\u001b[0;34m\u001b[0m\u001b[0m\n\u001b[1;32m    399\u001b[0m             \u001b[0mcoerce_float\u001b[0m\u001b[0;34m=\u001b[0m\u001b[0mcoerce_float\u001b[0m\u001b[0;34m,\u001b[0m \u001b[0mparse_dates\u001b[0m\u001b[0;34m=\u001b[0m\u001b[0mparse_dates\u001b[0m\u001b[0;34m,\u001b[0m\u001b[0;34m\u001b[0m\u001b[0m\n\u001b[0;32m--> 400\u001b[0;31m             chunksize=chunksize)\n\u001b[0m\u001b[1;32m    401\u001b[0m \u001b[0;34m\u001b[0m\u001b[0m\n\u001b[1;32m    402\u001b[0m     \u001b[0;32mtry\u001b[0m\u001b[0;34m:\u001b[0m\u001b[0;34m\u001b[0m\u001b[0m\n",
      "\u001b[0;32m~/anaconda3/lib/python3.6/site-packages/pandas/io/sql.py\u001b[0m in \u001b[0;36mread_query\u001b[0;34m(self, sql, index_col, coerce_float, params, parse_dates, chunksize)\u001b[0m\n\u001b[1;32m   1442\u001b[0m \u001b[0;34m\u001b[0m\u001b[0m\n\u001b[1;32m   1443\u001b[0m         \u001b[0margs\u001b[0m \u001b[0;34m=\u001b[0m \u001b[0m_convert_params\u001b[0m\u001b[0;34m(\u001b[0m\u001b[0msql\u001b[0m\u001b[0;34m,\u001b[0m \u001b[0mparams\u001b[0m\u001b[0;34m)\u001b[0m\u001b[0;34m\u001b[0m\u001b[0m\n\u001b[0;32m-> 1444\u001b[0;31m         \u001b[0mcursor\u001b[0m \u001b[0;34m=\u001b[0m \u001b[0mself\u001b[0m\u001b[0;34m.\u001b[0m\u001b[0mexecute\u001b[0m\u001b[0;34m(\u001b[0m\u001b[0;34m*\u001b[0m\u001b[0margs\u001b[0m\u001b[0;34m)\u001b[0m\u001b[0;34m\u001b[0m\u001b[0m\n\u001b[0m\u001b[1;32m   1445\u001b[0m         \u001b[0mcolumns\u001b[0m \u001b[0;34m=\u001b[0m \u001b[0;34m[\u001b[0m\u001b[0mcol_desc\u001b[0m\u001b[0;34m[\u001b[0m\u001b[0;36m0\u001b[0m\u001b[0;34m]\u001b[0m \u001b[0;32mfor\u001b[0m \u001b[0mcol_desc\u001b[0m \u001b[0;32min\u001b[0m \u001b[0mcursor\u001b[0m\u001b[0;34m.\u001b[0m\u001b[0mdescription\u001b[0m\u001b[0;34m]\u001b[0m\u001b[0;34m\u001b[0m\u001b[0m\n\u001b[1;32m   1446\u001b[0m \u001b[0;34m\u001b[0m\u001b[0m\n",
      "\u001b[0;32m~/anaconda3/lib/python3.6/site-packages/pandas/io/sql.py\u001b[0m in \u001b[0;36mexecute\u001b[0;34m(self, *args, **kwargs)\u001b[0m\n\u001b[1;32m   1419\u001b[0m             ex = DatabaseError(\n\u001b[1;32m   1420\u001b[0m                 \"Execution failed on sql '%s': %s\" % (args[0], exc))\n\u001b[0;32m-> 1421\u001b[0;31m             \u001b[0mraise_with_traceback\u001b[0m\u001b[0;34m(\u001b[0m\u001b[0mex\u001b[0m\u001b[0;34m)\u001b[0m\u001b[0;34m\u001b[0m\u001b[0m\n\u001b[0m\u001b[1;32m   1422\u001b[0m \u001b[0;34m\u001b[0m\u001b[0m\n\u001b[1;32m   1423\u001b[0m     \u001b[0;34m@\u001b[0m\u001b[0mstaticmethod\u001b[0m\u001b[0;34m\u001b[0m\u001b[0m\n",
      "\u001b[0;32m~/anaconda3/lib/python3.6/site-packages/pandas/compat/__init__.py\u001b[0m in \u001b[0;36mraise_with_traceback\u001b[0;34m(exc, traceback)\u001b[0m\n\u001b[1;32m    383\u001b[0m         \u001b[0;32mif\u001b[0m \u001b[0mtraceback\u001b[0m \u001b[0;34m==\u001b[0m \u001b[0mEllipsis\u001b[0m\u001b[0;34m:\u001b[0m\u001b[0;34m\u001b[0m\u001b[0m\n\u001b[1;32m    384\u001b[0m             \u001b[0m_\u001b[0m\u001b[0;34m,\u001b[0m \u001b[0m_\u001b[0m\u001b[0;34m,\u001b[0m \u001b[0mtraceback\u001b[0m \u001b[0;34m=\u001b[0m \u001b[0msys\u001b[0m\u001b[0;34m.\u001b[0m\u001b[0mexc_info\u001b[0m\u001b[0;34m(\u001b[0m\u001b[0;34m)\u001b[0m\u001b[0;34m\u001b[0m\u001b[0m\n\u001b[0;32m--> 385\u001b[0;31m         \u001b[0;32mraise\u001b[0m \u001b[0mexc\u001b[0m\u001b[0;34m.\u001b[0m\u001b[0mwith_traceback\u001b[0m\u001b[0;34m(\u001b[0m\u001b[0mtraceback\u001b[0m\u001b[0;34m)\u001b[0m\u001b[0;34m\u001b[0m\u001b[0m\n\u001b[0m\u001b[1;32m    386\u001b[0m \u001b[0;32melse\u001b[0m\u001b[0;34m:\u001b[0m\u001b[0;34m\u001b[0m\u001b[0m\n\u001b[1;32m    387\u001b[0m     \u001b[0;31m# this version of raise is a syntax error in Python 3\u001b[0m\u001b[0;34m\u001b[0m\u001b[0;34m\u001b[0m\u001b[0m\n",
      "\u001b[0;32m~/anaconda3/lib/python3.6/site-packages/pandas/io/sql.py\u001b[0m in \u001b[0;36mexecute\u001b[0;34m(self, *args, **kwargs)\u001b[0m\n\u001b[1;32m   1407\u001b[0m                 \u001b[0mcur\u001b[0m\u001b[0;34m.\u001b[0m\u001b[0mexecute\u001b[0m\u001b[0;34m(\u001b[0m\u001b[0;34m*\u001b[0m\u001b[0margs\u001b[0m\u001b[0;34m,\u001b[0m \u001b[0;34m**\u001b[0m\u001b[0mkwargs\u001b[0m\u001b[0;34m)\u001b[0m\u001b[0;34m\u001b[0m\u001b[0m\n\u001b[1;32m   1408\u001b[0m             \u001b[0;32melse\u001b[0m\u001b[0;34m:\u001b[0m\u001b[0;34m\u001b[0m\u001b[0m\n\u001b[0;32m-> 1409\u001b[0;31m                 \u001b[0mcur\u001b[0m\u001b[0;34m.\u001b[0m\u001b[0mexecute\u001b[0m\u001b[0;34m(\u001b[0m\u001b[0;34m*\u001b[0m\u001b[0margs\u001b[0m\u001b[0;34m)\u001b[0m\u001b[0;34m\u001b[0m\u001b[0m\n\u001b[0m\u001b[1;32m   1410\u001b[0m             \u001b[0;32mreturn\u001b[0m \u001b[0mcur\u001b[0m\u001b[0;34m\u001b[0m\u001b[0m\n\u001b[1;32m   1411\u001b[0m         \u001b[0;32mexcept\u001b[0m \u001b[0mException\u001b[0m \u001b[0;32mas\u001b[0m \u001b[0mexc\u001b[0m\u001b[0;34m:\u001b[0m\u001b[0;34m\u001b[0m\u001b[0m\n",
      "\u001b[0;31mDatabaseError\u001b[0m: Execution failed on sql 'SELECT row_to_json(europeansoccer) FROM europeansoccer': relation \"europeansoccer\" does not exist\nLINE 1: SELECT row_to_json(europeansoccer) FROM europeansoccer\n                                                ^\n"
     ]
    }
   ],
   "source": [
    "df=pd.read_sql('''SELECT row_to_json(europeansoccer) FROM europeansoccer''', con=conn)\n",
    "df.head(3)"
   ]
  },
  {
   "cell_type": "code",
   "execution_count": null,
   "metadata": {},
   "outputs": [],
   "source": []
  },
  {
   "cell_type": "code",
   "execution_count": null,
   "metadata": {},
   "outputs": [],
   "source": []
  },
  {
   "cell_type": "code",
   "execution_count": null,
   "metadata": {},
   "outputs": [],
   "source": []
  },
  {
   "cell_type": "code",
   "execution_count": null,
   "metadata": {},
   "outputs": [],
   "source": []
  }
 ],
 "metadata": {
  "kernelspec": {
   "display_name": "Python 3",
   "language": "python",
   "name": "python3"
  },
  "language_info": {
   "codemirror_mode": {
    "name": "ipython",
    "version": 3
   },
   "file_extension": ".py",
   "mimetype": "text/x-python",
   "name": "python",
   "nbconvert_exporter": "python",
   "pygments_lexer": "ipython3",
   "version": "3.6.4"
  }
 },
 "nbformat": 4,
 "nbformat_minor": 2
}
